Workbook

Sheet Сводка по сотрудникам
A1: Итоговое совещание Энергомикс, Коломна, 28–30.10.2026 — стоимость проезда на 1 человека
A2: Цены на 28.09.2026. «Эконом» — самые дешёвые билеты (в т. ч. ранние вылеты, ночные рейсы и поезда). «Удобный» — без подъёма среди ночи и без ночи в дороге: вылет не раньше ~09:00, приезд в Коломну до 23:00, обратно 31.10 днём после ночи в гостинице. Детали — лист «Маршруты».
A4: № | B4: ФИО | C4: Должность | D4: Город | E4: Способ | F4: ЭКОНОМ: туда, без багажа | G4: туда, с багажом | H4: обратно, без багажа | I4: обратно, с багажом | J4: трансферы | K4: доп. ночей | L4: ИТОГО эконом без багажа | M4: ИТОГО эконом с багажом | N4: УДОБНЫЙ: туда (с багажом) | O4: обратно (с багажом) | P4: трансферы | Q4: доп. ночей | R4: ИТОГО удобный | S4: В ПУТИ эконом (туда + обратно, дверь–дверь) | T4: В ПУТИ удобный (туда + обратно, дверь–дверь) | U4: Комментарий
A5: 1 | B5: Марченко В.Н. | C5: уточнить | D5: Омск | E5: Самолёт | F5: 7655 | G5: 10548 | H5: 9591 | I5: 12638 | J5: 3000 | K5: 0 | L5: =F5+H5+J5+K5*'Правила и допущения'!$B$3 | M5: =G5+I5+J5+K5*'Правила и допущения'!$B$3 | N5: 14270 | O5: 12639 | P5: 6500 | Q5: 2 | R5: =N5+O5+P5+Q5*'Правила и допущения'!$B$3 | S5: 20 ч 55 мин | T5: 20 ч 15 мин | U5: Удобный: вылет днём 27.10 + ночь; обратно дневных рейсов нет — вечер 31.10
A6: 2 | B6: Яруллин И.Р. | C6: уточнить | D6: Уфа | E6: Самолёт | F6: 6638 | G6: 9416 | H6: 8417 | I6: 11288 | J6: 1800 | K6: 0 | L6: =F6+H6+J6+K6*'Правила и допущения'!$B$3 | M6: =G6+I6+J6+K6*'Правила и допущения'!$B$3 | N6: 11268 | O6: 12118 | P6: 6000 | Q6: 1 | R6: =N6+O6+P6+Q6*'Правила и допущения'!$B$3 | S6: 18 ч 00 мин | T6: 15 ч 05 мин | U6: Эконом: вылет 07:00 и ночной обратно
A7: 3 | B7: Григорьев Д.С. | C7: Начальник склада | D7: Ревда | E7: Самолёт | F7: 7113 | G7: 10054 | H7: 10285 | I7: 13388 | J7: 5100 | K7: 0 | L7: =F7+H7+J7+K7*'Правила и допущения'!$B$3 | M7: =G7+I7+J7+K7*'Правила и допущения'!$B$3 | N7: 13395 | O7: 15996 | P7: 6000 | Q7: 1 | R7: =N7+O7+P7+Q7*'Правила и допущения'!$B$3 | S7: 19 ч 05 мин | T7: 16 ч 05 мин | U7: Вкл. такси Ревда—Кольцово
A8: 4 | B8: Воронков И.Н. | C8: Руководитель СФО | D8: Новосибирск | E8: Самолёт | F8: 7623 | G8: 10502 | H8: 8607 | I8: 11632 | J8: 2600 | K8: 1 | L8: =F8+H8+J8+K8*'Правила и допущения'!$B$3 | M8: =G8+I8+J8+K8*'Правила и допущения'!$B$3 | N8: 14236 | O8: 15333 | P8: 3400 | Q8: 1 | R8: =N8+O8+P8+Q8*'Правила и допущения'!$B$3 | S8: 21 ч 40 мин | T8: 21 ч 30 мин | U8: Удобный: днём в обе стороны
A9: 5 | B9: Макаров А.Г. | C9: уточнить | D9: Абакан | E9: Самолёт | F9: 19228 | G9: 25593 | H9: 21247 | I9: 25201 | J9: 2700 | K9: 1 | L9: =F9+H9+J9+K9*'Правила и допущения'!$B$3 | M9: =G9+I9+J9+K9*'Правила и допущения'!$B$3 | N9: 25201 | O9: 25201 | P9: 10000 | Q9: 1 | R9: =N9+O9+P9+Q9*'Правила и допущения'!$B$3 | S9: 20 ч 20 мин | T9: 21 ч 30 мин | U9: Обратно только ночной рейс (дневных нет)
A10: 6 | B10: Дёмин А.М. | C10: уточнить | D10: Красноярск | E10: Самолёт | F10: 10652 | G10: 14050 | H10: 9430 | I10: 12647 | J10: 3000 | K10: 1 | L10: =F10+H10+J10+K10*'Правила и допущения'!$B$3 | M10: =G10+I10+J10+K10*'Правила и допущения'!$B$3 | N10: 19270 | O10: 25343 | P10: 10000 | Q10: 1 | R10: =N10+O10+P10+Q10*'Правила и допущения'!$B$3 | S10: 22 ч 35 мин | T10: 22 ч 35 мин | U10: Удобный: днём в обе стороны
A11: 7 | B11: Иванова Е.В. | C11: уточнить | D11: Новокузнецк | E11: Самолёт | F11: 14784 | G11: 20644 | H11: 14784 | I11: 20644 | J11: 2400 | K11: 0 | L11: =F11+H11+J11+K11*'Правила и допущения'!$B$3 | M11: =G11+I11+J11+K11*'Правила и допущения'!$B$3 | N11: 20644 | O11: 18619 | P11: 8000 | Q11: 1 | R11: =N11+O11+P11+Q11*'Правила и допущения'!$B$3 | S11: 20 ч 25 мин | T11: 19 ч 35 мин | U11: Обратно дневных рейсов нет — вечер 31.10 после отдыха
A12: 8 | B12: Видяев А.А. | C12: уточнить | D12: Новосибирск | E12: Самолёт | F12: 7623 | G12: 10502 | H12: 8607 | I12: 11632 | J12: 2600 | K12: 1 | L12: =F12+H12+J12+K12*'Правила и допущения'!$B$3 | M12: =G12+I12+J12+K12*'Правила и допущения'!$B$3 | N12: 14236 | O12: 15333 | P12: 3400 | Q12: 1 | R12: =N12+O12+P12+Q12*'Правила и допущения'!$B$3 | S12: 21 ч 40 мин | T12: 21 ч 30 мин | U12: Удобный: днём в обе стороны
A13: 9 | B13: Малышев А.А. | C13: Начальник склада | D13: Новосибирск | E13: Самолёт | F13: 7623 | G13: 10502 | H13: 8607 | I13: 11632 | J13: 2600 | K13: 1 | L13: =F13+H13+J13+K13*'Правила и допущения'!$B$3 | M13: =G13+I13+J13+K13*'Правила и допущения'!$B$3 | N13: 14236 | O13: 15333 | P13: 3400 | Q13: 1 | R13: =N13+O13+P13+Q13*'Правила и допущения'!$B$3 | S13: 21 ч 40 мин | T13: 21 ч 30 мин | U13: Удобный: днём в обе стороны
A14: 10 | B14: Панкратова Е.С. | C14: уточнить | D14: Ижевск | E14: Самолёт | F14: 8158 | G14: 11683 | H14: 8158 | I14: 11683 | J14: 3000 | K14: 1 | L14: =F14+H14+J14+K14*'Правила и допущения'!$B$3 | M14: =G14+I14+J14+K14*'Правила и допущения'!$B$3 | N14: 11683 | O14: 11683 | P14: 6000 | Q14: 1 | R14: =N14+O14+P14+Q14*'Правила и допущения'!$B$3 | S14: 13 ч 45 мин | T14: 13 ч 45 мин | U14: Эконом = удобный
A15: 11 | B15: Асхадуллин А.М. | C15: уточнить | D15: Казань | E15: Самолёт / поезд | F15: 3265 | G15: 5995 | H15: 4270 | I15: 4270 | J15: 2400 | K15: 0 | L15: =F15+H15+J15+K15*'Правила и допущения'!$B$3 | M15: =G15+I15+J15+K15*'Правила и допущения'!$B$3 | N15: 7021 | O15: 7722 | P15: 6500 | Q15: 1 | R15: =N15+O15+P15+Q15*'Правила и допущения'!$B$3 | S15: 25 ч 10 мин | T15: 16 ч 15 мин | U15: Самолёт дешевле поезда; эконом обратно — ночной поезд
A16: 12 | B16: Егоров Р.Л. | C16: уточнить | D16: Набережные Челны | E16: Самолёт | F16: 4517 | G16: 7237 | H16: 5056 | I16: 7775 | J16: 4600 | K16: 1 | L16: =F16+H16+J16+K16*'Правила и допущения'!$B$3 | M16: =G16+I16+J16+K16*'Правила и допущения'!$B$3 | N16: 7237 | O16: 7775 | P16: 8500 | Q16: 1 | R16: =N16+O16+P16+Q16*'Правила и допущения'!$B$3 | S16: 15 ч 40 мин | T16: 15 ч 40 мин | U16: Эконом = удобный
A17: 13 | B17: Попов Д.М. | C17: уточнить | D17: Оренбург | E17: Самолёт | F17: 7050 | G17: 9636 | H17: 8429 | I17: 8429 | J17: 3000 | K17: 0 | L17: =F17+H17+J17+K17*'Правила и допущения'!$B$3 | M17: =G17+I17+J17+K17*'Правила и допущения'!$B$3 | N17: 9636 | O17: 15985 | P17: 6500 | Q17: 1 | R17: =N17+O17+P17+Q17*'Правила и допущения'!$B$3 | S17: 19 ч 25 мин | T17: 16 ч 25 мин | U17: Эконом обратно — ночной рейс 02:40
A18: 14 | B18: Ирышков Е.А. | C18: уточнить | D18: Пенза | E18: Авто | F18: ='Авто'!J2/2 | G18: ='Авто'!J2/2 | H18: ='Авто'!J2/2 | I18: ='Авто'!J2/2 | J18: 0 | K18: 0 | L18: =F18+H18+J18+K18*'Правила и допущения'!$B$3 | M18: =G18+I18+J18+K18*'Правила и допущения'!$B$3 | N18: ='Авто'!J2/2 | O18: ='Авто'!J2/2 | P18: 0 | Q18: 1 | R18: =N18+O18+P18+Q18*'Правила и допущения'!$B$3 | S18: 15 ч 00 мин | T18: 15 ч 00 мин | U18: Экипаж: Пенза. Удобный = обратно 31.10 утром + ночь
A19: 15 | B19: Симбирев И.В. | C19: Руководитель ПФО | D19: Саратов | E19: Поезд / самолёт | F19: 4013 | G19: 4013 | H19: 5012 | I19: 7630 | J19: 2400 | K19: 1 | L19: =F19+H19+J19+K19*'Правила и допущения'!$B$3 | M19: =G19+I19+J19+K19*'Правила и допущения'!$B$3 | N19: 8442 | O19: 7630 | P19: 4750 | Q19: 1 | R19: =N19+O19+P19+Q19*'Правила и допущения'!$B$3 | S19: 28 ч 30 мин | T19: 15 ч 05 мин | U19: Эконом: ночной поезд туда. Удобный: самолёт днём
A20: 16 | B20: Щеголев М.Г. | C20: уточнить | D20: Самара | E20: Поезд / самолёт | F20: 3594 | G20: 3594 | H20: 6905 | I20: 6905 | J20: 1800 | K20: 0 | L20: =F20+H20+J20+K20*'Правила и допущения'!$B$3 | M20: =G20+I20+J20+K20*'Правила и допущения'!$B$3 | N20: 7347 | O20: 8293 | P20: 6500 | Q20: 1 | R20: =N20+O20+P20+Q20*'Правила и допущения'!$B$3 | S20: 37 ч 25 мин | T20: 16 ч 20 мин | U20: Эконом: ночные поезда. Удобный: дневные рейсы
A21: 17 | B21: Ильин Д.С. | C21: уточнить | D21: Саранск | E21: Авто | F21: ='Авто'!J3/2 | G21: ='Авто'!J3/2 | H21: ='Авто'!J3/2 | I21: ='Авто'!J3/2 | J21: 0 | K21: 0 | L21: =F21+H21+J21+K21*'Правила и допущения'!$B$3 | M21: =G21+I21+J21+K21*'Правила и допущения'!$B$3 | N21: ='Авто'!J3/2 | O21: ='Авто'!J3/2 | P21: 0 | Q21: 1 | R21: =N21+O21+P21+Q21*'Правила и допущения'!$B$3 | S21: 14 ч 00 мин | T21: 14 ч 00 мин | U21: Экипаж: Саранск. Удобный = обратно 31.10 утром + ночь
A22: 18 | B22: Бобков А.А. | C22: уточнить | D22: Саратов | E22: Поезд / самолёт | F22: 4013 | G22: 4013 | H22: 5012 | I22: 7630 | J22: 2400 | K22: 1 | L22: =F22+H22+J22+K22*'Правила и допущения'!$B$3 | M22: =G22+I22+J22+K22*'Правила и допущения'!$B$3 | N22: 8442 | O22: 7630 | P22: 4750 | Q22: 1 | R22: =N22+O22+P22+Q22*'Правила и допущения'!$B$3 | S22: 28 ч 30 мин | T22: 15 ч 05 мин | U22: Эконом: ночной поезд туда. Удобный: самолёт днём
A23: 19 | B23: Самсонов С.А. | C23: уточнить | D23: Ульяновск | E23: Самолёт | F23: 4938 | G23: 7618 | H23: 5628 | I23: 8367 | J23: 1800 | K23: 1 | L23: =F23+H23+J23+K23*'Правила и допущения'!$B$3 | M23: =G23+I23+J23+K23*'Правила и допущения'!$B$3 | N23: 7618 | O23: 8367 | P23: 4500 | Q23: 1 | R23: =N23+O23+P23+Q23*'Правила и допущения'!$B$3 | S23: 14 ч 40 мин | T23: 14 ч 40 мин | U23: Эконом = удобный
A24: 20 | B24: Каратаев Д.В. | C24: уточнить | D24: Чебоксары | E24: Самолёт / поезд | F24: 4214 | G24: 6754 | H24: 3884 | I24: 3884 | J24: 3000 | K24: 0 | L24: =F24+H24+J24+K24*'Правила и допущения'!$B$3 | M24: =G24+I24+J24+K24*'Правила и допущения'!$B$3 | N24: 6754 | O24: 6754 | P24: 6500 | Q24: 1 | R24: =N24+O24+P24+Q24*'Правила и допущения'!$B$3 | S24: 24 ч 40 мин | T24: 14 ч 55 мин | U24: Туда самолёт днём; эконом обратно — ночной поезд
A25: 21 | B25: Рябов И.А. | C25: Начальник склада | D25: Ульяновск | E25: Самолёт | F25: 4938 | G25: 7618 | H25: 5628 | I25: 8367 | J25: 1800 | K25: 1 | L25: =F25+H25+J25+K25*'Правила и допущения'!$B$3 | M25: =G25+I25+J25+K25*'Правила и допущения'!$B$3 | N25: 7618 | O25: 8367 | P25: 4500 | Q25: 1 | R25: =N25+O25+P25+Q25*'Правила и допущения'!$B$3 | S25: 14 ч 40 мин | T25: 14 ч 40 мин | U25: Эконом = удобный
A26: 22 | B26: Федосеенко Т.А. | C26: уточнить | D26: Улан-Удэ | E26: Самолёт | F26: 16931 | G26: 21094 | H26: 21098 | I26: 28884 | J26: 2700 | K26: 0 | L26: =F26+H26+J26+K26*'Правила и допущения'!$B$3 | M26: =G26+I26+J26+K26*'Правила и допущения'!$B$3 | N26: 21094 | O26: 21094 | P26: 10000 | Q26: 1 | R26: =N26+O26+P26+Q26*'Правила и допущения'!$B$3 | S26: 23 ч 55 мин | T26: 24 ч 10 мин | U26: Обратно дневных рейсов нет — вечер 31.10, прилёт утром
A27: 23 | B27: Шевченко С.В. | C27: Межгород | D27: Иркутск | E27: Самолёт | F27: 12305 | G27: 15862 | H27: 12308 | I27: 15879 | J27: 1800 | K27: 1 | L27: =F27+H27+J27+K27*'Правила и допущения'!$B$3 | M27: =G27+I27+J27+K27*'Правила и допущения'!$B$3 | N27: 17607 | O27: 19332 | P27: 2200 | Q27: 1 | R27: =N27+O27+P27+Q27*'Правила и допущения'!$B$3 | S27: 22 ч 45 мин | T27: 23 ч 45 мин | U27: Группа 5 чел.: минивэн
A28: 24 | B28: Донской И.С. | C28: Оптовый отдел | D28: Иркутск | E28: Самолёт | F28: 12305 | G28: 15862 | H28: 12308 | I28: 15879 | J28: 1800 | K28: 1 | L28: =F28+H28+J28+K28*'Правила и допущения'!$B$3 | M28: =G28+I28+J28+K28*'Правила и допущения'!$B$3 | N28: 17607 | O28: 19332 | P28: 2200 | Q28: 1 | R28: =N28+O28+P28+Q28*'Правила и допущения'!$B$3 | S28: 22 ч 45 мин | T28: 23 ч 45 мин | U28: Группа 5 чел.: минивэн
A29: 25 | B29: Друсалевич В.В. | C29: уточнить | D29: Иркутск | E29: Самолёт | F29: 12305 | G29: 15862 | H29: 12308 | I29: 15879 | J29: 1800 | K29: 1 | L29: =F29+H29+J29+K29*'Правила и допущения'!$B$3 | M29: =G29+I29+J29+K29*'Правила и допущения'!$B$3 | N29: 17607 | O29: 19332 | P29: 2200 | Q29: 1 | R29: =N29+O29+P29+Q29*'Правила и допущения'!$B$3 | S29: 22 ч 45 мин | T29: 23 ч 45 мин | U29: Едет вместе с отцом (Друсалевич В.А.). Группа 5 чел.: минивэн
A30: 26 | B30: Бадмацыренов Т.Ц. | C30: уточнить | D30: Чита | E30: Самолёт | F30: 17671 | G30: 25050 | H30: 22835 | I30: 28993 | J30: 2400 | K30: 1 | L30: =F30+H30+J30+K30*'Правила и допущения'!$B$3 | M30: =G30+I30+J30+K30*'Правила и допущения'!$B$3 | N30: 28993 | O30: 28993 | P30: 6000 | Q30: 1 | R30: =N30+O30+P30+Q30*'Правила и допущения'!$B$3 | S30: 29 ч 10 мин | T30: 22 ч 35 мин | U30: Удобный: прямой рейс днём; обратно только вечерние рейсы
A31: 27 | B31: Петрова Т.А. | C31: уточнить | D31: Иркутск | E31: Самолёт | F31: 12305 | G31: 15862 | H31: 12308 | I31: 15879 | J31: 1800 | K31: 1 | L31: =F31+H31+J31+K31*'Правила и допущения'!$B$3 | M31: =G31+I31+J31+K31*'Правила и допущения'!$B$3 | N31: 17607 | O31: 19332 | P31: 2200 | Q31: 1 | R31: =N31+O31+P31+Q31*'Правила и допущения'!$B$3 | S31: 22 ч 45 мин | T31: 23 ч 45 мин | U31: Группа 5 чел.: минивэн
A32: 28 | B32: Летуновский В.М. | C32: Руководитель ЦЧР | D32: Воронеж | E32: Авто | F32: ='Авто'!J6/2 | G32: ='Авто'!J6/2 | H32: ='Авто'!J6/2 | I32: ='Авто'!J6/2 | J32: 0 | K32: 0 | L32: =F32+H32+J32+K32*'Правила и допущения'!$B$3 | M32: =G32+I32+J32+K32*'Правила и допущения'!$B$3 | N32: ='Авто'!J6/2 | O32: ='Авто'!J6/2 | P32: 0 | Q32: 1 | R32: =N32+O32+P32+Q32*'Правила и допущения'!$B$3 | S32: 11 ч 00 мин | T32: 11 ч 00 мин | U32: Экипаж: Воронеж (2 чел.). Удобный = обратно 31.10 утром + ночь
A33: 29 | B33: Иванищева А.В. | C33: Руководитель РЦ | D33: Липецк | E33: Авто | F33: ='Авто'!J5/2 | G33: ='Авто'!J5/2 | H33: ='Авто'!J5/2 | I33: ='Авто'!J5/2 | J33: 0 | K33: 0 | L33: =F33+H33+J33+K33*'Правила и допущения'!$B$3 | M33: =G33+I33+J33+K33*'Правила и допущения'!$B$3 | N33: ='Авто'!J5/2 | O33: ='Авто'!J5/2 | P33: 0 | Q33: 1 | R33: =N33+O33+P33+Q33*'Правила и допущения'!$B$3 | S33: 10 ч 00 мин | T33: 10 ч 00 мин | U33: Экипаж: Липецк (3 чел.). Удобный = обратно 31.10 утром + ночь
A34: 30 | B34: Майоров С.А. | C34: уточнить | D34: Астрахань | E34: Самолёт | F34: 7124 | G34: 9710 | H34: 7124 | I34: 9710 | J34: 3000 | K34: 1 | L34: =F34+H34+J34+K34*'Правила и допущения'!$B$3 | M34: =G34+I34+J34+K34*'Правила и допущения'!$B$3 | N34: 9710 | O34: 9710 | P34: 6500 | Q34: 1 | R34: =N34+O34+P34+Q34*'Правила и допущения'!$B$3 | S34: 17 ч 15 мин | T34: 17 ч 15 мин | U34: Эконом = удобный
A35: 31 | B35: Несмачный А.П. | C35: уточнить | D35: Белгород | E35: Поезд | F35: 2739 | G35: 2739 | H35: 3947 | I35: 3947 | J35: 1800 | K35: 0 | L35: =F35+H35+J35+K35*'Правила и допущения'!$B$3 | M35: =G35+I35+J35+K35*'Правила и допущения'!$B$3 | N35: 2739 | O35: 2674 | P35: 1800 | Q35: 1 | R35: =N35+O35+P35+Q35*'Правила и допущения'!$B$3 | S35: 31 ч 55 мин | T35: 22 ч 00 мин | U35: Туда Ласточка днём; эконом обратно — ночной поезд
A36: 32 | B36: Бондарев С.А. | C36: уточнить | D36: Брянск | E36: Авто | F36: ='Авто'!J7/2 | G36: ='Авто'!J7/2 | H36: ='Авто'!J7/2 | I36: ='Авто'!J7/2 | J36: 0 | K36: 0 | L36: =F36+H36+J36+K36*'Правила и допущения'!$B$3 | M36: =G36+I36+J36+K36*'Правила и допущения'!$B$3 | N36: ='Авто'!J7/2 | O36: ='Авто'!J7/2 | P36: 0 | Q36: 1 | R36: =N36+O36+P36+Q36*'Правила и допущения'!$B$3 | S36: 13 ч 00 мин | T36: 13 ч 00 мин | U36: Экипаж: Брянск + Орёл. Удобный = обратно 31.10 утром + ночь
A37: 33 | B37: Ситин В.А. | C37: уточнить | D37: Волгоград | E37: Самолёт | F37: 6406 | G37: 9061 | H37: 7155 | I37: 9893 | J37: 3000 | K37: 1 | L37: =F37+H37+J37+K37*'Правила и допущения'!$B$3 | M37: =G37+I37+J37+K37*'Правила и допущения'!$B$3 | N37: 9061 | O37: 9893 | P37: 6500 | Q37: 1 | R37: =N37+O37+P37+Q37*'Правила и допущения'!$B$3 | S37: 16 ч 50 мин | T37: 16 ч 50 мин | U37: Эконом = удобный
A38: 34 | B38: Штанько О.М. | C38: уточнить | D38: Воронеж | E38: Авто | F38: ='Авто'!J6/2 | G38: ='Авто'!J6/2 | H38: ='Авто'!J6/2 | I38: ='Авто'!J6/2 | J38: 0 | K38: 0 | L38: =F38+H38+J38+K38*'Правила и допущения'!$B$3 | M38: =G38+I38+J38+K38*'Правила и допущения'!$B$3 | N38: ='Авто'!J6/2 | O38: ='Авто'!J6/2 | P38: 0 | Q38: 1 | R38: =N38+O38+P38+Q38*'Правила и допущения'!$B$3 | S38: 11 ч 00 мин | T38: 11 ч 00 мин | U38: Экипаж: Воронеж (2 чел.). Удобный = обратно 31.10 утром + ночь
A39: 35 | B39: Кузнецов А.А. | C39: уточнить | D39: Липецк | E39: Авто | F39: ='Авто'!J5/2 | G39: ='Авто'!J5/2 | H39: ='Авто'!J5/2 | I39: ='Авто'!J5/2 | J39: 0 | K39: 0 | L39: =F39+H39+J39+K39*'Правила и допущения'!$B$3 | M39: =G39+I39+J39+K39*'Правила и допущения'!$B$3 | N39: ='Авто'!J5/2 | O39: ='Авто'!J5/2 | P39: 0 | Q39: 1 | R39: =N39+O39+P39+Q39*'Правила и допущения'!$B$3 | S39: 10 ч 00 мин | T39: 10 ч 00 мин | U39: Экипаж: Липецк (3 чел.). Удобный = обратно 31.10 утром + ночь
A40: 36 | B40: Мамонов С.В. | C40: уточнить | D40: Орёл | E40: Авто | F40: ='Авто'!J7/2 | G40: ='Авто'!J7/2 | H40: ='Авто'!J7/2 | I40: ='Авто'!J7/2 | J40: 0 | K40: 0 | L40: =F40+H40+J40+K40*'Правила и допущения'!$B$3 | M40: =G40+I40+J40+K40*'Правила и допущения'!$B$3 | N40: ='Авто'!J7/2 | O40: ='Авто'!J7/2 | P40: 0 | Q40: 1 | R40: =N40+O40+P40+Q40*'Правила и допущения'!$B$3 | S40: 13 ч 00 мин | T40: 13 ч 00 мин | U40: Экипаж: Брянск + Орёл. Удобный = обратно 31.10 утром + ночь
A41: 37 | B41: Козак С.С. | C41: уточнить | D41: Донецк | E41: Автобус / поезд через Ростов | F41: 3500 | G41: 3500 | H41: 4000 | I41: 4000 | J41: 1800 | K41: 1 | L41: =F41+H41+J41+K41*'Правила и допущения'!$B$3 | M41: =G41+I41+J41+K41*'Правила и допущения'!$B$3 | N41: 6793 | O41: 7132 | P41: 4800 | Q41: 0 | R41: =N41+O41+P41+Q41*'Правила и допущения'!$B$3 | S41: 51 ч 30 мин | T41: 59 ч 00 мин | U41: Ночь в дороге неизбежна; удобный — в купе. Вкл. Донецк—Ростов ~1 500 ₽ в каждую сторону
...

Sheet Маршруты
A1: Город | B1: Чел. | C1: Вариант | D1: Тип | E1: Транспорт | F1: Рейс / поезд | G1: Отправление | H1: Прибытие (время МСК) | I1: Куда прибывает | J1: Цена без багажа / билет, ₽ | K1: Цена с багажом, ₽ | L1: Как добраться до гостиницы | M1: В гостинице (ориентир) | N1: Выход из дома → в гостинице / выезд из гостиницы → дома | O1: Время в пути (дверь–дверь) | P1: Доп. ночь | Q1: Ссылка (Туту.ру) | R1: Примечание | S1: Проверка пробок (Яндекс/2ГИС)
A2: Омск | B2: 1 | C2: Туда | D2: Самый дешёвый | E2: Самолёт, Победа | F2: DP-6522 | G2: 28.10 07:05 (мест.) | H2: 28.10 07:45 | I2: Шереметьево | J2: 7655 | K2: 10548 | L2: Шереметьево: такси ~3 ч или аэроэкспресс → Белорусский + метро → Казанский + электричка | M2: ~11:30 | N2: 28.10 04:05 (мест.) → 28.10 11:30 МСК | O2: 10 ч 25 мин | Q2: https://avia.tutu.ru/f/Omsk/Moskva/?class=Y&travelers=1&route[0]=62-28102026-491 | R2: Ранний подъём (~04:00). Все прямые рейсы 28.10 вылетают до 08:05 | S2: проверить
A3: Омск | B3: 1 | C3: Туда (27.10) | D3: Удобный | E3: Самолёт, Аэрофлот | F3: SU-1689 | G3: 27.10 17:15 (мест.) | H3: 27.10 17:55 | I3: Шереметьево | J3: 10328 | K3: 14270 | L3: Такси ~3 ч (вечер 27.10) | M3: 27.10 ~22:00 | N3: 27.10 14:15 (мест.) → 27.10 22:00 МСК | O3: 10 ч 45 мин | P3: +1 ночь 27→28 | Q3: https://avia.tutu.ru/f/Omsk/Moskva/?class=Y&travelers=1&route[0]=62-27102026-491 | R3: Вылет днём накануне, ночь в гостинице — утром 28.10 отдохнувший
A4: Омск | B4: 1 | C4: Обратно | D4: Самый дешёвый | E4: Самолёт, Победа | F4: DP-6521 | G4: 30.10 23:45 | H4: 31.10 (мест.) | I4: Шереметьево | J4: 9591 | K4: 12638 | L4: Выезд из гостиницы 18:15; в аэропорту за 2 ч до вылета | N4: 30.10 18:15 МСК → 31.10 07:45 (мест.) | O4: 10 ч 30 мин | Q4: https://avia.tutu.ru/f/Moskva/Omsk/?class=Y&travelers=1&route[0]=491-30102026-62 | R4: Ночной рейс сразу после конференции
A5: Омск | B5: 1 | C5: Обратно | D5: Удобный | E5: Самолёт, Победа | F5: DP-6523 | G5: 31.10 22:00 | H5: 01.11 04:20 (мест.) | I5: Шереметьево | J5: 9591 | K5: 12639 | L5: 31.10 днём: электричка + аэроэкспресс или такси ~2 ч 30 мин | N5: 31.10 17:30 МСК → 01.11 06:00 (мест.) | O5: 9 ч 30 мин | P5: +1 ночь 30→31 | Q5: https://avia.tutu.ru/f/Moskva/Omsk/?class=Y&travelers=1&route[0]=491-31102026-62 | R5: Дневных рейсов в Омск нет. День 31.10 на отдых, вечерний вылет | S5: проверить
A6: Уфа | B6: 1 | C6: Туда | D6: Самый дешёвый | E6: Самолёт, Победа | F6: DP-436 | G6: 28.10 07:00 (мест.) | H6: 28.10 07:20 | I6: Внуково | J6: 6638 | K6: 9416 | L6: Внуково: метро → Казанский вокзал + электричка, или такси ~2 ч 45 мин | M6: ~10:45 | N6: 28.10 04:00 (мест.) → 28.10 10:45 МСК | O6: 8 ч 45 мин | Q6: https://avia.tutu.ru/f/Ufa/Moskva/?class=Y&travelers=1&route[0]=93-28102026-491 | R6: Ранний подъём | S6: проверить
A7: Уфа | B7: 1 | C7: Туда | D7: Удобный | E7: Самолёт, S7 | F7: S7-1136 | G7: 28.10 15:55 (мест.) | H7: 28.10 16:15 | I7: Домодедово | J7: 7884 | K7: 11268 | L7: Домодедово: такси 1 ч 45 мин + 40 мин на выход (группа 2–4 чел.) | M7: ~18:40 | N7: 28.10 12:55 (мест.) → 28.10 18:40 МСК | O7: 7 ч 45 мин | Q7: https://avia.tutu.ru/f/Ufa/Moskva/?class=Y&travelers=1&route[0]=93-28102026-491 | R7: Без экскурсии. Для экскурсии: SU-1237 12:45 → SVO 13:05, 8 521 / 11 889 | S7: проверить
A8: Уфа | B8: 1 | C8: Обратно | D8: Самый дешёвый | E8: Самолёт, Победа | F8: DP-435 | G8: 30.10 23:40 | H8: 31.10 (мест.) | I8: Внуково | J8: 8417 | K8: 11288 | L8: Выезд из гостиницы 18:15; в аэропорту за 2 ч до вылета | N8: 30.10 18:15 МСК → 31.10 05:30 (мест.) | O8: 9 ч 15 мин | Q8: https://avia.tutu.ru/f/Moskva/Ufa/?class=Y&travelers=1&route[0]=491-30102026-93 | R8: Ночной рейс
A9: Уфа | B9: 1 | C9: Обратно | D9: Удобный | E9: Самолёт, S7 | F9: S7-1135 | G9: 31.10 11:00 | H9: 31.10 15:10 (мест.) | I9: Домодедово | J9: 8639 | K9: 12118 | L9: 31.10 утро: такси до Домодедово ~1 ч 30 мин | N9: 31.10 07:30 МСК → 31.10 16:50 (мест.) | O9: 7 ч 20 мин | P9: +1 ночь 30→31 | Q9: https://avia.tutu.ru/f/Moskva/Ufa/?class=Y&travelers=1&route[0]=491-31102026-93 | S9: проверить
A10: Ревда (а/п Екатеринбург) | B10: 1 | C10: Туда | D10: Самый дешёвый | E10: Самолёт, Победа | F10: DP-404 | G10: 28.10 06:50 (мест.) | H10: 28.10 07:30 | I10: Внуково | J10: 7113 | K10: 10054 | L10: Внуково: метро → Казанский вокзал + электричка, или такси ~2 ч 45 мин | M10: ~10:55 | N10: 28.10 03:40 (мест.) → 28.10 10:55 МСК | O10: 9 ч 15 мин | Q10: https://avia.tutu.ru/f/Ekaterinburg/Moskva/?class=Y&travelers=1&route[0]=29-28102026-491 | R10: Выезд из Ревды ~03:50 | S10: проверить
A11: Ревда (а/п Екатеринбург) | B11: 1 | C11: Туда | D11: Удобный | E11: Самолёт, Уральские авиалинии | F11: U6-300 | G11: 28.10 12:00 (мест.) | H11: 28.10 12:40 | I11: Домодедово | J11: 10289 | K11: 13395 | L11: Домодедово: такси 1 ч 45 мин + 40 мин на выход (группа 2–4 чел.) | M11: ~15:05 | N11: 28.10 08:50 (мест.) → 28.10 15:05 МСК | O11: 8 ч 15 мин | Q11: https://avia.tutu.ru/f/Ekaterinburg/Moskva/?class=Y&travelers=1&route[0]=29-28102026-491 | R11: Выезд из Ревды ~09:00; к экскурсии успевает | S11: проверить
A12: Ревда (а/п Екатеринбург) | B12: 1 | C12: Обратно | D12: Самый дешёвый | E12: Самолёт, Уральские авиалинии | F12: U6-271 | G12: 30.10 23:45 | H12: 31.10 04:15 (мест.) | I12: Домодедово | J12: 10285 | K12: 13388 | L12: Выезд из гостиницы 18:15; в аэропорту за 2 ч до вылета | N12: 30.10 18:15 МСК → 31.10 06:05 (мест.) | O12: 9 ч 50 мин | Q12: https://avia.tutu.ru/f/Moskva/Ekaterinburg/?class=Y&travelers=1&route[0]=491-30102026-29 | R12: Ночной рейс
A13: Ревда (а/п Екатеринбург) | B13: 1 | C13: Обратно | D13: Удобный | E13: Самолёт, Уральские авиалинии | F13: U6-261 | G13: 31.10 10:00 | H13: 31.10 14:30 (мест.) | I13: Домодедово | J13: 11783 | K13: 15996 | L13: 31.10 утро: такси до Домодедово ~1 ч 30 мин (с группой Екатеринбурга) | N13: 31.10 06:30 МСК → 31.10 16:20 (мест.) | O13: 7 ч 50 мин | P13: +1 ночь 30→31 | Q13: https://avia.tutu.ru/f/Moskva/Ekaterinburg/?class=Y&travelers=1&route[0]=491-31102026-29 | S13: проверить
A14: Новосибирск | B14: 3 | C14: Туда | D14: Самый дешёвый | E14: Самолёт, Победа | F14: DP-6526 | G14: 28.10 07:50 (мест.) | H14: 28.10 08:20 | I14: Шереметьево | J14: 7623 | K14: 10502 | L14: Шереметьево: такси ~3 ч или аэроэкспресс → Белорусский + метро → Казанский + электричка | M14: ~12:00 | N14: 28.10 04:50 (мест.) → 28.10 12:00 МСК | O14: 11 ч 10 мин | Q14: https://avia.tutu.ru/f/Novosibirsk/Moskva/?class=Y&travelers=1&route[0]=58-28102026-491 | R14: Цена за 1 человека | S14: проверить
A15: Новосибирск | B15: 3 | C15: Туда | D15: Удобный | E15: Самолёт, Аэрофлот | F15: SU-1307 | G15: 28.10 10:15 (мест.) | H15: 28.10 10:45 | I15: Шереметьево | J15: 10426 | K15: 14236 | L15: Такси ~3 ч, втроём одна машина | M15: ~14:30 | N15: 28.10 07:15 (мест.) → 28.10 14:30 МСК | O15: 11 ч 15 мин | Q15: https://avia.tutu.ru/f/Novosibirsk/Moskva/?class=Y&travelers=1&route[0]=58-28102026-491 | R15: К экскурсии успевают
A16: Новосибирск | B16: 3 | C16: Обратно | D16: Самый дешёвый | E16: Самолёт, Победа | F16: DP-6525 | G16: 31.10 22:45 | H16: 01.11 (мест.) | I16: Шереметьево | J16: 8607 | K16: 11632 | L16: 31.10 днём: электричка + аэроэкспресс или такси ~2 ч 30 мин | N16: 31.10 18:15 МСК → 01.11 08:45 (мест.) | O16: 10 ч 30 мин | P16: +1 ночь 30→31 | Q16: https://avia.tutu.ru/f/Moskva/Novosibirsk/?class=Y&travelers=1&route[0]=491-31102026-58 | R16: Ночной рейс | S16: проверить
A17: Новосибирск | B17: 3 | C17: Обратно | D17: Удобный | E17: Самолёт, Аэрофлот | F17: SU-1076 | G17: 31.10 12:20 | H17: 31.10 20:25 (мест.) | I17: Шереметьево | J17: 11503 | K17: 15333 | L17: 31.10 утро: такси ~2 ч 30 мин, втроём | N17: 31.10 07:50 МСК → 31.10 22:05 (мест.) | O17: 10 ч 15 мин | P17: +1 ночь 30→31 | Q17: https://avia.tutu.ru/f/Moskva/Novosibirsk/?class=Y&travelers=1&route[0]=491-31102026-58 | R17: Дома вечером 31.10 | S17: проверить
A18: Красноярск | B18: 1 | C18: Туда | D18: Самый дешёвый | E18: Самолёт, Победа | F18: DP-6548 | G18: 28.10 08:10 (мест.) | H18: 28.10 09:25 | I18: Шереметьево | J18: 10652 | K18: 14050 | L18: Шереметьево: такси ~3 ч или аэроэкспресс → Белорусский + метро → Казанский + электричка | M18: ~13:05 | N18: 28.10 05:10 (мест.) → 28.10 13:05 МСК | O18: 11 ч 55 мин | Q18: https://avia.tutu.ru/ | R18: Подъём ~05:00 | S18: проверить
A19: Красноярск | B19: 1 | C19: Туда | D19: Удобный | E19: Самолёт, Аэрофлот | F19: SU-1483 | G19: 28.10 11:05 (мест.) | H19: 28.10 12:20 | I19: Шереметьево | J19: 15358 | K19: 19270 | L19: Шереметьево: такси ~3 ч или аэроэкспресс → Белорусский + метро → Казанский + электричка | M19: ~16:00 | N19: 28.10 08:05 (мест.) → 28.10 16:00 МСК | O19: 11 ч 55 мин | Q19: https://avia.tutu.ru/ | S19: проверить
A20: Красноярск | B20: 1 | C20: Обратно | D20: Самый дешёвый | E20: Самолёт, Победа | F20: DP-6547 | G20: 31.10 22:35 | H20: 01.11 (мест.) | I20: Шереметьево | J20: 9430 | K20: 12647 | L20: 31.10 днём: электричка + аэроэкспресс или такси ~2 ч 30 мин | N20: 31.10 18:05 МСК → 01.11 08:45 (мест.) | O20: 10 ч 40 мин | P20: +1 ночь 30→31 | Q20: https://avia.tutu.ru/ | R20: Ночной рейс | S20: проверить
A21: Красноярск | B21: 1 | C21: Обратно | D21: Удобный | E21: Самолёт, Аэрофлот | F21: SU-1488 | G21: 31.10 13:05 | H21: 31.10 вечер (мест.) | I21: Шереметьево | J21: 20707 | K21: 25343 | L21: 31.10 утро: такси ~2 ч 30 мин | N21: 31.10 08:35 МСК → 31.10 23:15 (мест.) | O21: 10 ч 40 мин | P21: +1 ночь 30→31 | Q21: https://avia.tutu.ru/ | R21: Дома вечером 31.10 | S21: проверить
A22: Абакан | B22: 1 | C22: Туда | D22: Самый дешёвый | E22: Самолёт, S7 | F22: S7-2594 | G22: 28.10 07:15 (мест.) | H22: 28.10 08:25 | I22: Домодедово | J22: 19228 | K22: 25593 | L22: Домодедово: такси 1 ч 45 мин + 40 мин на выход (группа 2–4 чел.) | M22: ~10:50 | N22: 28.10 05:00 (мест.) → 28.10 10:50 МСК | O22: 9 ч 50 мин | Q22: https://avia.tutu.ru/ | R22: Ранний подъём | S22: проверить
A23: Абакан | B23: 1 | C23: Туда | D23: Удобный | E23: Самолёт, Аэрофлот | F23: SU-1479 | G23: 28.10 09:55 (мест.) | H23: 28.10 11:00 | I23: Шереметьево | J23: 21247 | K23: 25201 | L23: Шереметьево: такси ~3 ч или аэроэкспресс → Белорусский + метро → Казанский + электричка | M23: ~14:40 | N23: 28.10 07:40 (мест.) → 28.10 14:40 МСК | O23: 11 ч 00 мин | Q23: https://avia.tutu.ru/ | R23: С багажом дешевле S7 | S23: проверить
A24: Абакан | B24: 1 | C24: Обратно | D24: Самый дешёвый = Удобный | E24: Самолёт, Аэрофлот | F24: SU-1478 | G24: 31.10 23:55 | H24: 01.11 (мест.) | I24: Шереметьево | J24: 21247 | K24: 25201 | L24: 31.10 днём: электричка + аэроэкспресс или такси ~2 ч 30 мин | N24: 31.10 19:25 МСК → 01.11 09:55 (мест.) | O24: 10 ч 30 мин | P24: +1 ночь 30→31 | Q24: https://avia.tutu.ru/ | R24: Дневных рейсов в Абакан нет (есть только вечерние/ночные). День 31.10 на отдых | S24: проверить
A25: Новокузнецк | B25: 1 | C25: Туда | D25: Самый дешёвый = Удобный | E25: Самолёт, S7 | F25: S7-2626 | G25: 28.10 09:00 (мест.) | H25: 28.10 10:00 | I25: Домодедово | J25: 14784 | K25: 20644 | L25: Домодедово: такси 1 ч 45 мин + 40 мин на выход (группа 2–4 чел.) | M25: ~12:25 | N25: 28.10 06:45 (мест.) → 28.10 12:25 МСК | O25: 9 ч 40 мин | Q25: https://avia.tutu.ru/ | S25: проверить
A26: Новокузнецк | B26: 1 | C26: Обратно | D26: Самый дешёвый | E26: Самолёт, S7 | F26: S7-2625 | G26: 30.10 23:35 | H26: 31.10 (мест.) | I26: Домодедово | J26: 14784 | K26: 20644 | L26: Выезд из гостиницы 18:15; в аэропорту за 2 ч до вылета | N26: 30.10 18:15 МСК → 31.10 09:00 (мест.) | O26: 10 ч 45 мин | Q26: https://avia.tutu.ru/ | R26: Ночной рейс сразу после конференции
A27: Новокузнецк | B27: 1 | C27: Обратно | D27: Удобный | E27: Самолёт, Аэрофлот | F27: SU-1458 | G27: 31.10 22:35 | H27: 01.11 (мест.) | I27: Шереметьево | J27: 14806 | K27: 18619 | L27: 31.10 днём: электричка + аэроэкспресс или такси ~2 ч 30 мин | N27: 31.10 18:05 МСК → 01.11 08:00 (мест.) | O27: 9 ч 55 мин | P27: +1 ночь 30→31 | Q27: https://avia.tutu.ru/ | R27: Дневных рейсов нет. День 31.10 на отдых, вечерний вылет | S27: проверить
A28: Иркутск | B28: 5 | C28: Туда | D28: Самый дешёвый | E28: Самолёт, Уральские авиалинии | F28: U6-106 | G28: 28.10 07:35 (мест.) | H28: 28.10 09:10 | I28: Домодедово | J28: 12305 | K28: 15862 | L28: Домодедово: такси 1 ч 45 мин + 40 мин на выход (группа 2–4 чел.) — минивэн на 5 чел. | M28: ~11:35 | N28: 28.10 04:35 (мест.) → 28.10 11:35 МСК | O28: 12 ч 00 мин | Q28: https://avia.tutu.ru/ | R28: Цена за 1 человека | S28: проверить
A29: Иркутск | B29: 5 | C29: Туда | D29: Удобный | E29: Самолёт, Аэрофлот | F29: SU-6732 | G29: 28.10 11:05 (мест.) | H29: 28.10 12:25 | I29: Шереметьево | J29: 13727 | K29: 17607 | L29: Минивэн ~3 ч | M29: ~16:05 | N29: 28.10 08:05 (мест.) → 28.10 16:05 МСК | O29: 13 ч 00 мин | Q29: https://avia.tutu.ru/ | R29: Вылет днём
A30: Иркутск | B30: 5 | C30: Обратно | D30: Самый дешёвый | E30: Самолёт, Уральские авиалинии | F30: U6-105 | G30: 31.10 19:25 | H30: 01.11 (мест.) | I30: Домодедово | J30: 12308 | K30: 15879 | L30: 31.10: минивэн до Домодедово | N30: 31.10 15:55 МСК → 01.11 07:40 (мест.) | O30: 10 ч 45 мин | P30: +1 ночь 30→31 | Q30: https://avia.tutu.ru/ | R30: Ночной перелёт | S30: проверить
A31: Иркутск | B31: 5 | C31: Обратно | D31: Удобный | E31: Самолёт, S7 | F31: S7-3021 | G31: 31.10 12:05 | H31: 31.10 вечер (мест.) | I31: Домодедово | J31: 13005 | K31: 19332 | L31: 31.10 утро: такси до Домодедово ~1 ч 30 мин, минивэн | N31: 31.10 08:35 МСК → 01.11 00:20 (мест.) | O31: 10 ч 45 мин | P31: +1 ночь 30→31 | Q31: https://avia.tutu.ru/ | R31: Дома вечером 31.10 | S31: проверить
A32: Улан-Удэ | B32: 1 | C32: Туда | D32: Самый дешёвый = Удобный | E32: Самолёт, Аэрофлот | F32: SU-1455 | G32: 28.10 10:05 (мест.) | H32: 28.10 11:45 | I32: Шереметьево | J32: 16931 | K32: 21094 | L32: Шереметьево: такси ~3 ч или аэроэкспресс → Белорусский + метро → Казанский + электричка | M32: ~15:25 | N32: 28.10 07:50 (мест.) → 28.10 15:25 МСК | O32: 12 ч 35 мин | Q32: https://avia.tutu.ru/ | S32: проверить
A33: Улан-Удэ | B33: 1 | C33: Обратно | D33: Самый дешёвый | E33: Самолёт, S7 | F33: S7-3033 | G33: 30.10 22:20 | H33: 31.10 (мест.) | I33: Домодедово | J33: 21098 | K33: 28884 | L33: Выезд из гостиницы 18:15; в аэропорту за 2 ч до вылета | N33: 30.10 18:15 МСК → 31.10 10:35 (мест.) | O33: 11 ч 20 мин | Q33: https://avia.tutu.ru/ | R33: Ночной рейс сразу после конференции
A34: Улан-Удэ | B34: 1 | C34: Обратно | D34: Удобный | E34: Самолёт, Аэрофлот | F34: SU-1454 | G34: 31.10 21:55 | H34: 01.11 утро (мест.) | I34: Шереметьево | J34: 16931 | K34: 21094 | L34: 31.10 днём: электричка + аэроэкспресс или такси ~2 ч 30 мин | N34: 31.10 17:25 МСК → 01.11 10:00 (мест.) | O34: 11 ч 35 мин | P34: +1 ночь 30→31 | Q34: https://avia.tutu.ru/ | R34: Дневных рейсов нет. День 31.10 на отдых; прилёт утром | S34: проверить
A35: Чита | B35: 1 | C35: Туда | D35: Самый дешёвый | E35: Самолёт, S7 (пересадка Иркутск) | F35: S7-6426 + S7-3018 | G35: 28.10 03:20 (мест.) | H35: 28.10 10:55 | I35: Домодедово | J35: 17671 | K35: 25050 | L35: Домодедово: такси 1 ч 45 мин + 40 мин на выход (группа 2–4 чел.) | M35: ~13:20 | N35: 28.10 01:05 (мест.) → 28.10 13:20 МСК | O35: 18 ч 15 мин | Q35: https://avia.tutu.ru/f/Chita/Moskva/?class=Y&travelers=1&route[0]=100-28102026-491 | R35: Ночной вылет | S35: проверить
A36: Чита | B36: 1 | C36: Туда | D36: Удобный | E36: Самолёт, Уральские авиалинии, прямой | F36: U6-94 | G36: 28.10 09:20 (мест.) | H36: 28.10 10:20 | I36: Домодедово | J36: 22835 | K36: 28993 | L36: Домодедово: такси 1 ч 45 мин + 40 мин на выход (группа 2–4 чел.) | M36: ~12:45 | N36: 28.10 07:05 (мест.) → 28.10 12:45 МСК | O36: 11 ч 40 мин | Q36: https://avia.tutu.ru/f/Chita/Moskva/?class=Y&travelers=1&route[0]=100-28102026-491 | R36: Прямой рейс днём | S36: проверить
A37: Чита | B37: 1 | C37: Обратно | D37: Самый дешёвый = Удобный | E37: Самолёт, Уральские авиалинии | F37: U6-93 | G37: 31.10 19:40 | H37: 01.11 (мест.) | I37: Домодедово | J37: 22835 | K37: 28993 | L37: 31.10: такси до Домодедово | N37: 31.10 16:10 МСК → 01.11 09:05 (мест.) | O37: 10 ч 55 мин | P37: +1 ночь 30→31 | Q37: https://avia.tutu.ru/f/Moskva/Chita/?class=Y&travelers=1&route[0]=491-31102026-100 | R37: Дневных рейсов нет; вылет вечером после отдыха | S37: проверить
A38: Самара | B38: 1 | C38: Туда (27.10) | D38: Самый дешёвый | E38: Поезд, купе | F38: 015М | G38: 27.10 15:41 | H38: 28.10 05:40 | I38: Москва, Казанский | J38: 3594 | K38: 3594 | L38: Казанский вокзал → электричка до ст. Коломна (490–620 ₽) + такси 10 мин (~300 ₽) (07:22 → 09:15) | M38: ~09:30 | N38: 27.10 14:55 (мест.) → 28.10 09:30 МСК | O38: 19 ч 35 мин | P38: ранний заезд | Q38: https://www.tutu.ru/poezda/ | R38: Ночь в поезде | S38: проверить
A39: Самара | B39: 1 | C39: Туда | D39: Удобный | E39: Самолёт, Победа | F39: DP-422 | G39: 28.10 14:45 (мест.) | H39: 28.10 15:45 | I39: Внуково | J39: 4644 | K39: 7347 | L39: Внуково: метро → Казанский вокзал + электричка, или такси ~2 ч 45 мин | M39: ~19:10 | N39: 28.10 11:45 (мест.) → 28.10 19:10 МСК | O39: 8 ч 25 мин | Q39: https://avia.tutu.ru/f/Samara/Moskva/?class=Y&travelers=1&route[0]=74-28102026-491 | R39: Для экскурсии: SU-1603 10:25 → SVO 11:15, 6 454 / 9 763 | S39: проверить
A40: Самара | B40: 1 | C40: Обратно | D40: Самый дешёвый | E40: Поезд, купе | F40: 014Е | G40: 30.10 21:40 | H40: 31.10 12:18 | I40: Москва, Казанский | J40: 6905 | K40: 6905 | L40: Электричка 18:43 → Казанский 20:47 | N40: 30.10 18:15 МСК → 31.10 13:05 (мест.) | O40: 17 ч 50 мин | Q40: https://www.tutu.ru/poezda/ | R40: Ночь в поезде
...

Sheet Авто
A1: Экипаж | B1: Кто едет | C1: Чел. | D1: Маршрут | E1: Км до Коломны (в одну сторону) | F1: Время в пути | G1: Топливо туда-обратно, ₽ | H1: Платные дороги туда-обратно, ₽ | I1: Итого на машину, ₽ | J1: На 1 чел., ₽ | K1: Выезд / приезд (эконом) | L1: Примечание
A2: Пенза | B2: Ирышков Е.А. | C2: 1 | D2: Пенза — М-5 — Шацк — Рязань — Коломна | E2: 560 | F2: ~7 ч 30 мин | G2: =E2*2*'Правила и допущения'!$B$4/100*'Правила и допущения'!$B$5 | H2: 0 | I2: =G2+H2 | J2: =I2/C2 | K2: 27.10 выезд ~13:00 → 20:30; или 28.10 06:30 → 14:00 | L2: Близко к лимиту 600 км. Совместно с Саранском — только при встрече на М-5 (р-н Шацка), заезд в Саранск даёт ~630 км
A3: Саранск | B3: Ильин Д.С. | C3: 1 | D3: Саранск — Краснослободск — М-5 — Рязань — Коломна | E3: 500 | F3: ~7 ч | G3: =E3*2*'Правила и допущения'!$B$4/100*'Правила и допущения'!$B$5 | H3: 0 | I3: =G3+H3 | J3: =I3/C3 | K3: 28.10 выезд 07:00 → 14:00 | L3: Альтернатива — поезд 041Й (лист «Маршруты»)
A4: Тамбов | B4: Горелкин Д.Е. | C4: 1 | D4: Тамбов — Р-22 — Рязань — Коломна | E4: 390 | F4: ~5 ч | G4: =E4*2*'Правила и допущения'!$B$4/100*'Правила и допущения'!$B$5 | H4: 0 | I4: =G4+H4 | J4: =I4/C4 | K4: 28.10 выезд 09:00 → 14:00 | L4: Обратно 30.10 после 18:00 — дома ~23:30
A5: Липецк (3 чел.) | B5: Иванищева А.В., Кузнецов А.А., Зайцев С.А. | C5: 3 | D5: Липецк — Данков — Скопин — Рязань — Коломна | E5: 370 | F5: ~5 ч | G5: =E5*2*'Правила и допущения'!$B$4/100*'Правила и допущения'!$B$5 | H5: 0 | I5: =G5+H5 | J5: =I5/C5 | K5: 28.10 выезд 09:00 → 14:00 | L5: Одна машина на троих — самый выгодный вариант
A6: Воронеж (2 чел.) | B6: Летуновский В.М., Штанько О.М. | C6: 2 | D6: Воронеж — М-4 «Дон» — Кашира — Коломна | E6: 450 | F6: ~5 ч 30 мин | G6: =E6*2*'Правила и допущения'!$B$4/100*'Правила и допущения'!$B$5 | H6: 3600 | I6: =G6+H6 | J6: =I6/C6 | K6: 28.10 выезд 08:30 → 14:00 | L6: Платные участки М-4 — ориентир ~1 800 ₽ в одну сторону, проверить. Можно захватить 1 чел. из Липецка (+~40 км)
A7: Брянск + Орёл | B7: Бондарев С.А. (водитель), Мамонов С.В. | C7: 2 | D7: Брянск — Орёл — Тула — Венёв — Коломна | E7: 500 | F7: ~6 ч 30 мин | G7: =E7*2*'Правила и допущения'!$B$4/100*'Правила и допущения'!$B$5 | H7: 0 | I7: =G7+H7 | J7: =I7/C7 | K7: 28.10 выезд из Брянска 07:00, Орёл ~09:00 → 13:30 | L7: Орёл по пути, крюк не нужен. Если едут отдельно: Орёл → Коломна ~360 км, Брянск ~440 км (через Калугу)
A8: Н. Новгород + Владимир (3 чел.) | B8: Бабкин В.А., Меднов В.А. (из Н. Новгорода), Шабанов Р.В. (забрать во Владимире) | C8: 3 | D8: Н. Новгород — М-12 — Владимир — Петушки — Покров — Орехово-Зуево — Егорьевск — Коломна | E8: 430 | F8: ~6 ч | G8: =E8*2*'Правила и допущения'!$B$4/100*'Правила и допущения'!$B$5 | H8: 3000 | I8: =G8+H8 | J8: =I8/C8 | K8: 28.10 выезд из Н. Новгорода 08:00 → Владимир ~10:30 (забрать Шабанова) → Коломна ~14:00 | L8: Владимир по пути — крюк не нужен. М-12 платная, ~1 500 ₽ в одну сторону (ориентир); по бесплатной М-7 +~40 мин. Обратно 30.10 после 18:00: Владимир ~21:30, Н. Новгород ~00:30 — для водителя лучше 31.10 утром
A9: Калуга | B9: Макеев С.И. | C9: 1 | D9: Калуга — Таруса — Серпухов — Ступино — Коломна | E9: 230 | F9: ~3 ч 30 мин | G9: =E9*2*'Правила и допущения'!$B$4/100*'Правила и допущения'!$B$5 | H9: 0 | I9: =G9+H9 | J9: =I9/C9 | K9: 28.10 выезд 10:30 → 14:00 | L9: Если своей машины нет — поезд до Киевского вокзала (лист «Маршруты»)
A11: Расстояния и время — ориентир; точный маршрут и пробки проверить в Яндекс Картах. Обратно: эконом — выезд 30.10 в 18:15; удобный — 31.10 утром + доп. ночь.

Sheet Группы такси
A1: Дата / аэропорт | B1: Группа | C1: Кто (город, рейс, прилёт/вылет) | D1: Чел. | E1: Сбор / выезд | F1: Машин | G1: Цена на машину, ₽ | H1: На 1 чел., ₽ | I1: Комментарий
A2: 27.10 Шереметьево (удобный) | B2: Ш-0 | C2: Омск SU-1689 17:55 | D2: 1 | E2: сразу после прилёта | F2: 1 | G2: 5000 | H2: =G2*F2/D2 | I2: Или аэроэкспресс + электричка
A3: 28.10 Домодедово (удобный) | B3: Д-1 | C3: Новокузнецк S7-2626 10:00; Екатеринбург U6-272 10:10 — группа 9 чел. + Нижний Тагил; Чита U6-94 10:20 | D3: 12 | E3: сбор ~10:45 | F3: 2 | G3: 4000 | H3: =G3*F3/D3 | I3: 2 минивэна (заказать заранее)
A4: 28.10 Домодедово (удобный) | B4: Д-2 | C4: Ревда U6-300 12:40 | D4: 1 | E4: ~13:10 | F4: 1 | G4: 3000 | H4: =G4*F4/D4
A5: 28.10 Домодедово (удобный) | B5: Д-3 | C5: Уфа S7-1136 16:15; Ижевск S7-1166 20:05 | D5: 1 | E5: по прилёту | F5: 1 | G5: 3000 | H5: =G5*F5/D5 | I5: Прилёты далеко по времени — отдельные такси
A6: 28.10 Шереметьево (удобный) | B6: Ш-1 | C6: Новосибирск SU-1307 10:45 (3 чел.); Абакан SU-1479 11:00; Чебоксары DP-6808 11:45; Улан-Удэ SU-1455 11:45; Казань N4-60 11:55 | D6: 7 | E6: сбор ~12:15 | F6: 1 | G6: 7000 | H6: =G6*F6/D6 | I6: Минивэн на 7–8 мест
A7: 28.10 Шереметьево (удобный) | B7: Ш-2 | C7: Волгоград DP-6966 12:10; Красноярск SU-1483 12:20; Иркутск SU-6732 12:25 (5 чел.) | D7: 7 | E7: сбор ~12:50 | F7: 1 | G7: 7000 | H7: =G7*F7/D7 | I7: Минивэн
A8: 28.10 Шереметьево (удобный) | B8: Ш-3 | C8: Астрахань DP-6962 13:45 | D8: 1 | E8: ~14:15 | F8: 1 | G8: 5000 | H8: =G8*F8/D8 | I8: Или аэроэкспресс + электричка
A9: 28.10 Шереметьево (удобный) | B9: Ш-4 | C9: Челябинск SU-1421 17:10; Саратов DP-6864 18:20 (2 чел.); Наб. Челны DP-6846 18:30; Оренбург N4-78 18:55 | D9: 5 | E9: сбор ~19:15 | F9: 1 | G9: 7000 | H9: =G9*F9/D9 | I9: Минивэн; в гостинице ~22:30
A10: 28.10 Внуково (удобный) | B10: В-1 | C10: Ульяновск DP-466 11:50 (2 чел.); Магнитогорск A4-7062 13:00 | D10: 3 | E10: сбор ~13:20 | F10: 1 | G10: 4500 | H10: =G10*F10/D10
A11: 28.10 Внуково (удобный) | B11: В-2 | C11: Самара DP-422 15:45; Тюмень UT-464 18:55 | D11: 1 | E11: по прилёту | F11: 1 | G11: 4500 | H11: =G11*F11/D11 | I11: Отдельные такси
A12: 31.10 → Домодедово (удобный) | B12: О-1 | C12: Екатеринбург + Нижний Тагил U6-261 10:00 (10 чел.); Ревда U6-261 | D12: 11 | E12: выезд ~07:00 | F12: 2 | G12: 4000 | H12: =G12*F12/D12 | I12: 2 минивэна
A13: 31.10 → Домодедово (удобный) | B13: О-2 | C13: Уфа S7-1135 11:00; Иркутск S7-3021 12:05 (5 чел.) | D13: 6 | E13: выезд ~08:30 | F13: 1 | G13: 4000 | H13: =G13*F13/D13 | I13: Минивэн
A14: 31.10 → Домодедово (удобный) | B14: О-3 | C14: Ижевск S7-1165 15:10; Чита U6-93 19:40 | D14: 1 | E14: по времени рейсов | F14: 1 | G14: 3000 | H14: =G14*F14/D14 | I14: Отдельные такси
A15: 31.10 → Шереметьево (удобный) | B15: О-4 | C15: Челябинск SU-1420 10:50; Магнитогорск SU-1420 10:50 | D15: 2 | E15: выезд ~06:15 | F15: 1 | G15: 5000 | H15: =G15*F15/D15
A16: 31.10 → Шереметьево (удобный) | B16: О-5 | C16: Новосибирск SU-1076 12:20 (3 чел.); Красноярск SU-1488 13:05 | D16: 4 | E16: выезд ~07:45 | F16: 1 | G16: 5000 | H16: =G16*F16/D16
A17: 31.10 → Шереметьево (удобный) | B17: О-6 | C17: Астрахань DP-6963 13:50; Наб. Челны DP-6845 14:10; Самара DP-6581 14:15; Оренбург SU-1248 15:30 | D17: 4 | E17: выезд ~09:15 | F17: 1 | G17: 5000 | H17: =G17*F17/D17 | I17: Или электричка + аэроэкспресс
A18: 31.10 → Шереметьево (удобный) | B18: О-7 | C18: Казань DP-6843 17:30; Волгоград DP-6969 18:35; Чебоксары DP-6815 19:30 | D18: 3 | E18: выезд ~13:00 | F18: 1 | G18: 5000 | H18: =G18*F18/D18
A19: 31.10 → Шереметьево (удобный) | B19: О-8 | C19: Улан-Удэ SU-1454 21:55; Омск DP-6523 22:00; Новокузнецк SU-1458 22:35; Абакан SU-1478 23:55 | D19: 4 | E19: выезд ~17:00 | F19: 1 | G19: 5000 | H19: =G19*F19/D19 | I19: Вечерние рейсы в Сибирь
A20: 31.10 → Внуково (удобный) | B20: О-9 | C20: Тюмень UT-463 10:00 | D20: 1 | E20: выезд ~06:45 | F20: 1 | G20: 4500 | H20: =G20*F20/D20
A21: 31.10 → Внуково (удобный) | B21: О-10 | C21: Саратов DP-475 17:55 (2 чел.); Ульяновск DP-485 19:35 (2 чел.) | D21: 4 | E21: выезд ~13:30 | F21: 1 | G21: 4500 | H21: =G21*F21/D21
A22: 30.10 → аэропорты (эконом) | B22: Э-1 | C22: Домодедово: Новокузнецк S7-2625 23:35; Улан-Удэ S7-3033 22:20; Ревда/Уфа U6-271/—. Внуково: Уфа DP-435 23:40; Екатеринбург DP-403 23:50 (10 чел.); Челябинск DP-413 23:45. Шереметьево: Омск DP-6521 23:45; Тюмень DP-6561 23:50; Магнитогорск SU-1428 00:40 | D22: 20 | E22: выезд 18:15 | F22: 4 | G22: 6000 | H22: =G22*F22/D22 | I22: Эконом-вариант: ночные рейсы сразу после конференции

Sheet Как добраться до гостиницы
A1: Гостиница «Коломна»: пл. Советская, 2, Коломна. Тел. +7 (496) 612-18-96. Заезд с 14:00.
A3: Откуда | B3: Как ехать | C3: Время (с пробками) | D3: Стоимость | E3: Совет
A4: Аэропорт Домодедово | B4: Такси напрямую (~95 км, М-4 / Каширское ш.) | C4: 1 ч 45 мин (ср днём) + 40 мин на выход с багажом | D4: 2 500–4 500 ₽ за машину | E4: Лучший вариант, особенно группой 2–4 чел.
A5: Аэропорт Шереметьево | B5: Аэроэкспресс → Белорусский вокзал (~40 мин) → метро до Комсомольской (~20 мин) → электричка с Казанского до ст. Коломна → такси 10 мин | C5: ~4 ч | D5: 700 ₽ (650 ₽ при покупке заранее; «Вместе» 2 400 ₽ на 4 чел.) + 490–620 ₽ + ~300 ₽ | E5: Дёшево; зависит от расписания электричек
A6: Аэропорт Шереметьево | B6: Такси напрямую (~150 км) | C6: ~3 ч + 40 мин | D6: 4 200–5 800 ₽ за машину | E6: Выгодно для 3–4 чел.
A7: Аэропорт Внуково | B7: Метро (ст. «Аэропорт Внуково») → Комсомольская → электричка с Казанского → такси. Аэроэкспресса больше нет | C7: ~3 ч 30 мин | D7: ~90 ₽ + 490–620 ₽ + ~300 ₽
A8: Аэропорт Внуково | B8: Такси напрямую (~140 км) | C8: ~2 ч 45 мин + 40 мин | D8: 4 100–5 500 ₽ за машину
A9: Казанский вокзал | B9: Электричка до ст. «Коломна» (не Голутвин — ближе к гостинице), затем такси | C9: 1 ч 40 мин – 2 ч 25 мин (РЭКС ~1 ч 45 мин) | D9: «Стандарт плюс» 490 ₽, РЭКС 620 ₽; такси ~300 ₽ | E9: «Ласточек» до Коломны в продаже нет
A10: Павелецкий / Курский / Киевский / Восточный | B10: Метро или МЦД до Комсомольской (Казанский вокзал), дальше как выше | C10: +20–30 мин | D10: ~90 ₽ | E10: Закладывать не меньше 40 мин на пересадку
A11: Станция Голутвин | B11: Такси до гостиницы | C11: ~15 мин | D11: ~350 ₽ | E11: Сюда приходят поезда дальнего следования (напр. 213*С из Воронежа в 04:50)
A14: Электрички Казанский вокзал → Коломна, 28.10 (ср) | C14: Коломна → Казанский вокзал, 30.10 (пт)
A15: 07:22 → 09:15 | C15: 18:43 → 20:47
A16: 08:47 → 10:28 (РЭКС) | C16: 19:43 → 22:10
A17: 09:48 → 11:36 | C17: 20:10 → 22:30
A18: перерыв до 12:54 | C18: 21:01 → 22:38 (РЭКС)
A19: 12:54 → 15:15 | C19: 21:41 → 00:01
A20: 13:35 → 15:22 (РЭКС)
A22: Расписание электричек: https://www.tutu.ru/prigorod/ (Москва Казанская — Коломна). Проверка пробок: Яндекс Карты или 2ГИС → «Время и дата отправления».

Sheet Правила и допущения
A1: Параметры расчёта (можно менять — итоги пересчитаются)
A3: Доп. ночь в гостинице «Коломна», ₽ | B3: 4000 | C3: Номер от ~3 050 ₽; уточнить корпоративный тариф: +7 (496) 612-18-96
A4: Расход топлива, л/100 км | B4: 10 | C4: Средний легковой автомобиль
A5: Цена бензина, ₽/л | B5: 65 | C5: АИ-95, октябрь 2026 — ориентир
A7: Правила подбора маршрутов
A8: Ключевые даты | B8: Экскурсия 28.10 в 16:00 (заселиться к 15:00). Если к 15:00 не успеть — приехать так, чтобы к 9:00 29.10 выспаться. Окончание конференции 30.10 в 18:00.
A9: Гостиница | B9: «Коломна», пл. Советская, 2. Заезд с 14:00. Тел. +7 (496) 612-18-96. При раннем приезде (поезд в 05–07 ч) — камера хранения или ранний заезд, договориться заранее.
A10: Два варианта | B10: «Самый дешёвый» — минимальная цена (ранние вылеты, ночные рейсы, ночные поезда допускаются). «Удобный» — без подъёма среди ночи и без ночи в дороге. Если самый дешёвый вариант и есть удобный — показан один (пометка «Самый дешёвый = Удобный»).
A11: Критерии удобного варианта | B11: Туда: вылет/отправление не раньше ~09:00 (подъём не раньше 5:30–6:00); приезд в Коломну до 22–23 ч 28.10 (экскурсию можно пропустить) или днём накануне с ночёвкой. Обратно: не ночным рейсом сразу после конференции, а 31.10 днём после ночи в гостинице (+1 ночь). Вылеты в 23:00–00:40 и ночные поезда отнесены к эконому.
A12: Где удобного обратного рейса нет | B12: Омск, Абакан, Новокузнецк, Улан-Удэ, Чита: из Москвы летают только вечером/ночью (разница во времени 3–6 ч). В удобном варианте — вечерний рейс 31.10 после дня отдыха. Магнитогорск: прямые только 00:40 и 07:40 — удобный через Челябинск + автобус. Донецк: ночной переезд неизбежен, удобный — в купе.
A13: Самолёты | B13: Только эконом. Две цены: без багажа (только ручная кладь) и с багажом. Цены — обычные, за один билет (групповых тарифов и скидок нет), на 28.09.2026, быстро меняются. Когда на один рейс летят несколько человек, билеты лучше купить заранее и сразу.
A14: Аэропорт | B14: В аэропорту минимум за 2 часа до вылета (Москва и крупные города); в небольших городах — за 1,5 часа. Учитывать время подъёма и дорогу до аэропорта: рейсы с вылетом до ~07:00 означают подъём среди ночи.
A15: Пробки | B15: Время такси заложено с учётом пробок: среда 28.10 днём (DME→Коломна 1 ч 45 мин, SVO ~3 ч, VKO ~2 ч 45 мин + 40 мин на выход с багажом); пятница 30.10 вечером, выезд 18:15: DME ~2 ч, VKO ~3 ч, SVO ~3 ч 30 мин; суббота 31.10 утром: DME 1 ч 30 мин, VKO 2 ч 15 мин, SVO 2 ч 30 мин.
A16: Вечерний вылет 30.10 возможен, если | B16: Домодедово — вылет не раньше ~22:15; Внуково — ~23:15; Шереметьево — ~23:45. Иначе — 31.10 + доп. ночь.
A17: Поезда | B17: Только купе или сидячие, без плацкарта. Не более суток в пути. Идеал — вечером сел, днём в Коломне.
A18: Машина | B18: Для городов до 600 км. Совместные поездки предложены, если по пути. Для водителей после конференции безопаснее выезд 31.10 утром (+ ночь).
A19: Проверка пробок | B19: Яндекс Карты или 2ГИС: построить маршрут → «Время и дата отправления» → выбрать 28.10 и нужный час. Покажут прогноз по статистике пробок.
... A21: Что проверить | B21: Строки с пометкой «проверить» посчитаны по расписанию соседнего дня. Донецк: автобусы из ДНР продаются у перевозчиков, не на Туту; многие ходят через день — уточнить дату.
